Workbook

Sheet GeneralSettings
A1: Name | B1: Value | C1: Dev Value | D1: Test Value | E1: Description
A2: Process Settings
A3: ProcessName | B3: 189_HR_Workday_Casiers_Judiciaires | E3: Name of your process. This name appears in Process folders and Mail subject
A4: DispatcherStyle | B4: Separate Dispatcher - Performer | E4: Choose whether or not you want to create a seperate UiPath project for the dispatcher. See Documentation Chapter 3 for more details. Make sure Prod and Test value are same.
A5: ScreenResolutionExpected | B5: 1920x1080 | E5: Used to log comparison of expected resolution with actual resolution.
A6: BusinessProcessName | B6: Accelerated Framework | E6: This is a logging field which allows you to group the log data of two or more subprocesses under the same business process name
A7: RoboyoFrameworkVersion | B7: 22.10.5 | E7: Used to log the version of the Framework currently in use.
A8: ProcessesToKill | B8: chrome | E8: String containing the names of the processes to be killed in the KillAllProcesses workflow. Default Delimiter " ; ". Example: iexplore;chrome; …
A9: ProcessLanguage | B9: French | E9: Possible values are: "English", "German", "Spanish". Check the Sheet LanguageSettings for an overview
A11: Orchestrator Settings
A12: OrchestratorQueueName | B12: senico | C12: senico | E12: Orchestrator Queue Name. Be sure to match this name with the one from the server.
A13: OrchestratorQueueFolder | B13: Shared | C13: Shared | E13: Folder name. The value must match a folder defined in Orchestrator and queue specified as OrchestratorQueueName should be created in this folder. For classic folders leave the value field empty.
A14: Orchestrator_SpecificContent | B14: ID | E14: Provide a specific content value for reporting
A15: OrchestratorAssetFolder | B15: Shared | C15: Shared
A16: EncryptQueueItems | B16: FALSE | E16: Enables or disables Queue Item Encryption. The Encryption Key should be stored securely and be rotated at least once every two years by the NIST, see Section 5.3.6, Page 52 for more information. https://nvlpubs.nist.gov/nistpubs/SpecialPublications/NIST.SP.800-57pt1r4.pdf
A17: EncryptionKey | B17: ExampleKeyName | E17: Name of the Credentials Asset where the Password is equal to the EncryptionKey
A18: QueueItemFieldsToEncrypt | B18: Example,Field
A19: FieldsToEncryptSeparator | B19: ,
A20: SageUserCredential | B20: SageCredentials | C20: SageCredentials
A22: SharePoint Settings
A25: RaiseAlert | B25: TRUE | C25: FALSE | E25: If set to True, an Alert will be raised to Orchestrator when Maximum Retries had been reached.
A26: Orchestrator_TerminateMessage | B26: =IF(B9="English",LanguageSettings!$B2,IF(B9="Spanish",LanguageSettings!$D2,LanguageSettings!$C2)) -> L’exécution du travail a rencontré une exception système, veuillez consulter le fichier journal et le rapport d’expédition | E26: To update Orchestrator Job Status, if a Job encountered a system exception in Init or after Max system errors reached.
A28: Email Settings
A29: EmailType | B29: SMTP | E29: If False, Mails will be sent through SMTP. The SMPT-settings (below) are only relevant if this variable is set to False. Delete the SMTP Settings if you use Outlook
A30: EmailAccount | B30: plyon@lfdj.com | D30: plyon@lfdj.com | E30: Mail account used to sent Mails
A31: EmailSendOnBehalfOf | E31: Mail account to send on behalf of, if supported
A32: EmailName | E32: Email name used when sending out emails (ie, account is support@roboyo.de but name can be "RPA Support Group" or anything you want)
A33: EmailTemplateLanguage | B33: French | E33: Chooses which Mail_Template will be used. Options: English, German, Spanish
A34: UseEmailCredentials | B34: FALSE | E34: If set to True it will retrieve the email credentials from Orchestrator.
A35: EmailCredential_OrchFolder | E35: Orchestrator folder where email credentials are stored
A36: EmailCredential_CredName | E36: Name of the credential in Orchestrator which stores the SMTP-User and SMTP-Password
A37: SMTP_Host | B37: mailgateway.prod.fdj.fr | C37: mailgateway.int.fdj.fr | D37: mailgateway.int.fdj.fr | E37: Network address
A38: SMTP_Port | B38: 25 | E38: Network Port to sent mails through. In many cases this will be 587. For Gmail you can use 465
A39: EmailSensitivity
A41: HTML_Template_Name | B41: Configuration\Mail_Template_%Language%.html
A42: RobotName | B42: Robot RH | E42: The Robot name appears in the mail messages
A44: SendMailForSR | B44: TRUE | C44: FALSE
A45: StatusReport_Mail_Subject | B45: =SUBSTITUTE(IF(B9="English",LanguageSettings!$B3,IF(B9="Spanish",LanguageSettings!$D3,LanguageSettings!$C3)),"%ProcessName%",B3) -> 189_HR_Workday_Casiers_Judiciaires - Status Report | C45: ="DEV - "&SUBSTITUTE(IF(B9="English",LanguageSettings!$B3,IF(B9="Spanish",LanguageSettings!$D3,LanguageSettings!$C3)),"%ProcessName%",B3) -> DEV - 189_HR_Workday_Casiers_Judiciaires - Status Report | D45: ="INT - "&SUBSTITUTE(IF(B9="English",LanguageSettings!$B3,IF(B9="Spanish",LanguageSettings!$D3,LanguageSettings!$C3)),"%ProcessName%",B3) -> INT - 189_HR_Workday_Casiers_Judiciaires - Status Report | E45: Subject of mail which contained StatusReport, which is sent at the end of the processrun
A46: StatusReport_Mail_CustomMessage | B46: =IF(B9="English",LanguageSettings!$B4,IF(B9="Spanish",LanguageSettings!$D4,LanguageSettings!$C4)) -> <p>Vous trouverez le rapport de dispatch joint à ce mail. %SRSummary%</p> | E46: Custom message in StatusReport mail. See Also Sheet LanguageSettings
A47: StatusReport_Mail_BreakReportMessage | B47: =IF(B9="English",LanguageSettings!$B5,IF(B9="Spanish",LanguageSettings!$D5,LanguageSettings!$C5)) -> <p>Le processus s’est arrêté après avoir atteint le nombre maximum d’erreurs inattendues autorisées. Vous trouverez le rapport de dispatch joint à ce mail.</p> | E47: Custom message in StatusReport mail if the robot has aborted after reaching a configurable number of System errors [Constants: MaxSystemErrorNumber]. See Also Sheet LanguageSettings
...

Sheet CustomSettings
A1: Name | B1: Value | C1: Dev Value | D1: Test Value | E1: Description
A2: foreignCountriesAllowed | B2: True | E2: Value must be "True" or "False".
A3: reassignTaskAllowed | B3: False | E3: Value must be "True" or "False".
A4: deleteLocalDocumentAllowed | B4: True | E4: Value must be "True" or "False".
A5: ProcessName_DocumentRow | B5: Criminal Record
A6: FileName_SavePDF | B6: Casier.pdf
A7: MailTo_AddressCC | B7: plyon@lfdj.com
A8: MailSubject_NOCriminalRecords | B8: Casiers_Judiciaires - Casier judiciaire vierge pour le collaborateur %COLLABORATEUR% , Matricule : %MATRICULE% | C8: DEV - Casiers_Judiciaires - Casier judiciaire vide pour le collaborateur %COLLABORATEUR% , Matricule : %MATRICULE% | D8: INT - Casiers_Judiciaires - Casier judiciaire vide pour le collaborateur %COLLABORATEUR% , Matricule : %MATRICULE%
A9: MailBody_NOCriminalRecords | B9: <p>Je vous informe que le casier judiciaire du collaborateur %COLLABORATEUR% , Matricule : %MATRICULE% , est vierge et conforme. Aucune mention n'a été trouvée lors de l'analyse automatisée. </p>
A10: MailSubject_CriminalRecords | B10: Casiers_Judiciaires - Mentions sur le casier judiciaire du collaborateur %COLLABORATEUR% , Matricule : %MATRICULE% | C10: DEV - Casiers_Judiciaires - Mentions sur le casier judiciaire du collaborateur %COLLABORATEUR% , Matricule : %MATRICULE% | D10: INT - Casiers_Judiciaires - Mentions sur le casier judiciaire du collaborateur %COLLABORATEUR% , Matricule : %MATRICULE%
A11: MailBody_CriminalRecords | B11: <p> Nous vous informons que lors de la vérification du casier judiciaire du collaborateur %COLLABORATEUR% , Matricule : %MATRICULE%, des mentions ont été relevées. </p> <p> Nous vous prions de bien vouloir examiner ces mentions et de prendre les mesures nécessaires en fonction de notre politique interne. </p> <p> Merci de votre compréhension et de votre coopération. </p>
A12: FileName_UploadPDF | B12: \Input\PDF\SuppressionCasierJudicaireFDJGroupe.pdf
A13: Regex_NoCriminalRecords | B13: (Relevé des condamnations)[\s\r\n\D\d]{0,270}(Réf)
A14: Downloads_FolderPath | B14: C:\Users\A993551\Downloads\ | C14: C:\Users\A992736\Downloads\ | D14: D:\RUN RPA\189_HR_Workday_Casiers_Judiciaires\Test\Downloads\ | E14: Directory download path for temporary PDF file. You need to put a "\" at the end of the directory
A15: NomUsage_Text | B15: Nom d'usage
A17: AllowedExtension | B17: pdf,png, jpg
A18: MaxMB | B18: 20
A19: PathDownloadAttachements | B19: C:\Users\senyoneadmin\Documents\UiPath\SENICO\Data | C19: C:\Users\senyoneadmin\Documents\UiPath\SENICO\Data
A20: DomainName | B20: senyone.sn | C20: senyone.sn
A21: AnnuaireFolder | B21: ANNUAIRE | C21: ANNUAIRE
A22: AnnuaireFileName | B22: Annuaire.xlsx | C22: Annuaire.xlsx
A23: AnnuaireFileUrl | B23: https://senyone.sharepoint.com/:x:/s/ServicesRH/EcNvdO692pJDpE007LBfz-4B4wA7J_ulFRarWxCrdjw_0A?e=PuwZaQ | C23: https://senyone.sharepoint.com/:x:/s/ServicesRH/EcNvdO692pJDpE007LBfz-4B4wA7J_ulFRarWxCrdjw_0A?e=PuwZaQ
A24: AnnuaireFileRange | B24: Feuil1 | C24: Feuil1
A25: BroadCastSenderMail | B25: reception@senico.sn, direction@senico.sn | C25: reception@senico.sn, direction@senico.sn
A26: MailBox | B26: Boîte de réception | C26: Boîte de réception
A27: MailBoxRPA | B27: SENICO | C27: SENICO
A28: Type_document | B28: invoices | C28: invoices
A29: Document_confidence | B29: 0.5 | C29: 0.5
A31: SharePointParentFolder | B31: https://senyone.sharepoint.com/:f:/s/ServicesRH/IgAHDSym0Y4OQIWg94J_tGliAenLgaPpG8A1Ae0OItEM6ao?e=uLdM8K | C31: https://senyone.sharepoint.com/:f:/s/ServicesRH/IgAHDSym0Y4OQIWg94J_tGliAenLgaPpG8A1Ae0OItEM6ao?e=uLdM8K
A32: SharePointFolder_DSI | B32: https://senyone.sharepoint.com/:f:/s/ServicesRH/IgCMdysN-cJVRJTscSIcJfwIAYAb2Lu0lMUQAZ6-yaJH8vY?e=9PGs0O | C32: https://senyone.sharepoint.com/:f:/s/ServicesRH/IgCMdysN-cJVRJTscSIcJfwIAYAb2Lu0lMUQAZ6-yaJH8vY?e=9PGs0O
A33: SharePointFolder_ACHAT | B33: https://senyone.sharepoint.com/:f:/s/ServicesRH/IgCTljwmzmNwTagOpMvdqTmXAcwB8OEiJtqwdd7yPuz56sI?e=FzInGY | C33: https://senyone.sharepoint.com/:f:/s/ServicesRH/IgCTljwmzmNwTagOpMvdqTmXAcwB8OEiJtqwdd7yPuz56sI?e=FzInGY
A34: SharePointFolder_LOG | B34: https://senyone.sharepoint.com/:f:/s/ServicesRH/IgCLpiGYyV_bTrgLo6SYiv52AYs001WXAI7EYue45KdVqmQ?e=UBwrRS | C34: https://senyone.sharepoint.com/:f:/s/ServicesRH/IgCLpiGYyV_bTrgLo6SYiv52AYs001WXAI7EYue45KdVqmQ?e=UBwrRS
A35: SharePointFolder_A_DETERMINER | B35: https://senyone.sharepoint.com/:f:/s/ServicesRH/IgAbdU_t7HW4So2YznO6G_5wAUB7d_upIMseXAUSlG6b6oo?e=ppSRsv | C35: https://senyone.sharepoint.com/:f:/s/ServicesRH/IgAbdU_t7HW4So2YznO6G_5wAUB7d_upIMseXAUSlG6b6oo?e=ppSRsv
A37: MailValidatorBody | B37: "Bonjour," & vbCrLf & vbCrLf & "Certaines informations sont manquantes ou non fiables pour la facture suivante :" & vbCrLf & vbCrLf & "Veuillez compléter les champs suivants : " & vbCrLf & vbCrLf & | C37: "Bonjour," & vbCrLf & vbCrLf & "Certaines informations sont manquantes ou non fiables pour la facture suivante :" & vbCrLf & vbCrLf & "Veuillez compléter les champs suivants : " & vbCrLf & vbCrLf &
A38: MailValidatorSubject | B38: Complément d'informations pour la facture | C38: Complément d'informations pour la facture
A39: MailValidatorSignature | B39: "Merci de répondre en respectant exactement ce format." & vbCrLf & vbCrLf & "Cordialement," & vbCrLf & "Service Automatisation UiPath" | C39: "Merci de répondre en respectant exactement ce format." & vbCrLf & vbCrLf & "Cordialement," & vbCrLf & "Service Automatisation UiPath"
A40: MailValidatorAdress | B40: fallou@senyone.sn | C40: fallou@senyone.sn
A41: MailValidatorAdressCC | B41: fallou@senyone.sn | C41: fallou@senyone.sn
A43: Asset_Workday_UI_HomepageURL | B43: Workday_UI_HomepageURL
A44: Asset_Workday_API_GetWorkerCredentials | B44: Workday_API_GetWorkerCredentials
...

Sheet Constants
A1: Name | B1: Value | C1: Dev Value | D1: Test Value | E1: Description
A2: General Constants
A3: MaxRetryNumber | B3: 0 | E3: Must be 0 if working with Orchestrator queues. If > 0, the robot will retry the same transaction which failed with application exception. Must be integer.
A4: MaxSystemErrorNumber | B4: 200 | E4: Maximum System errors encountered in Process-State, before the process aborts. Must be Integer.
A5: MaxTransactionsProcessed | B5: 2 | E5: Number of transactions to proceed. If set to 0, all transaction data will be proceed. Must be Integer.
A6: MaxInitAppsRetries | B6: 3 | E6: Number of times to retry Init Applications workflow in Init State if encounters a System Exception. If set to 0, Init Applications wil not be retried. Must be Integer.
A8: TimeoutShort | B8: 5 | E8: Timeout short value in seconds, for activities which are likely to fail. Must be integer
A9: TimeoutMedium | B9: 30 | E9: Timeout medium value in seconds. Must be integer
A10: TimeoutLong | B10: 120 | E10: Timeout short value in seconds, for slow apps. Must be integer
A12: DelayShort | B12: 1 | E12: Delay short value in seconds, for activities where it is necessary to wait a little. Must be integer
A13: DelayMedium | B13: 15 | E13: Delay medium value in seconds, for activities where it is necessary to wait a moderate amount of time. Must be integer
A14: DelayLong | B14: 60 | E14: Delay long value in seconds, for activities where it is necessary to wait a long time. Must be integer
A16: AccuracyLow | B16: 0.6 | E16: Image accuracy low value, for images that have high contrast. Must be double
A17: AccuracyMedium | B17: 0.8 | E17: Image accuracy medium value, for images that have normal contrast. Must be double
A18: AccuracyHigh | B18: 0.9 | E18: Image accuracy high value, for images that have low contrast. Must be double
A20: LogMessage_GetTransactionData | B20: Processing Transaction Number: | E20: Static part of logging message. Calling Get Transaction Data
A21: LogMessage_GetTransactionDataError | B21: Error getting transaction data for Transaction Number: | E21: Static part of logging message. Error retrieving Transaction Data.
A22: LogMessage_Success | B22: Transaction Successful. | E22: Static part of logging message. Processed Transaction succesful
A23: LogMessage_BusinessRuleException | B23: Business rule exception. | E23: Static part of logging message. Processed Transaction failed with business exception
A24: LogMessage_ApplicationException | B24: System exception. | E24: Static part of logging message. Processed Transaction failed with application exception
A25: LogMessage_GetMessageMail | B25: Processing Transaction Number: | E25: Static part of logging message. Calling Get Message Mail
A27: RecordsProcessedCount | B27: 0 | E27: Do NOT change. Should be set to 0. Default value for Process Analysis (Must be integer)
A28: SystemErrorCount | B28: 0 | E28: Do NOT change. Should be set to 0. Default value for Process break (Must be integer)
A29: BusinessErrorCount | B29: 0 | E29: Do NOT change. Should be set to 0. Default value for Process break (Must be integer)
A31: ProcessFilesFolder | B31: D:\RUN RPA\189_HR_Workday_Casiers_Judiciaires\Prod | C31: D:\RUN RPA\189_HR_Workday_Casiers_Judiciaires\Dev | D31: D:\RUN RPA\189_HR_Workday_Casiers_Judiciaires\Test | E31: Folder where all subfolders for temporary files, such as screenshots, logfiles and statusReports are created.
A32: ArchiveTempFilesAfterDays | B32: 7 | E32: Number of days before temporary files will be moved to the archive-folder.
A34: QueueActivitiesRetryNumber | B34: 3 | E34: The number of times the Retry Scope sequence is to be retried. Must be integer
A35: QueueActivitiesRetryInterval | B35: 5 | E35: Specifies the amount of time (in seconds) between each retry. Must be integer
A37: Custom Constants
A38: AddNewConstantsHere

Sheet Assets
A1: Name | B1: Value | C1: OrchestratorAssetFolder | D1: Required | E1: Description (Assets will always overwrite other config)
A2: Sage_UI_HomepageURL | B2: Sage_UI_HomepageURL | C2: Shared
A3: sharePoint_Parent_Folder | B3: sharePoint_Parent_Folder | C3: Shared

Sheet LanguageSettings
A1: Settings | B1: English | C1: French | D1: Spanish | E1: German
A2: Orchestrator_TerminateMessage | B2: Job execution encountered system exception, Please see Log File and Status report | C2: L’exécution du travail a rencontré une exception système, veuillez consulter le fichier journal et le rapport d’expédition | D2: La ejecución del trabajo ha encontrado una excepción del sistema, por favor, vea el archivo de registro y el informe de estado | E2: Bei der Auftragsausführung ist eine Systemausnahme aufgetreten, siehe Log File und Status Report
A3: StatusReport_Mail_Subject | B3: %ProcessName% - Status Report | C3: %ProcessName% - Status Report
A4: StatusReport_Mail_CustomMessage | B4: <p>You will find the Status Report attached to this mail %SRSummary%</p> | C4: <p>Vous trouverez le rapport de dispatch joint à ce mail. %SRSummary%</p> | D4: <p>Adjunto recibirá el informe de estado de la ejecución. %SRSummary%</p> | E4: <p>Anbei erhalten Sie das Status Report der Roboter Durchlauf. %SRSummary%</p>
A5: StatusReport_Mail_BreakReportMessage | B5: <p>The process stopped after reaching the maximum number of Unexpected Errors allowed. You will find the status report attached to this Mail.</p> | C5: <p>Le processus s’est arrêté après avoir atteint le nombre maximum d’erreurs inattendues autorisées. Vous trouverez le rapport de dispatch joint à ce mail.</p> | D5: <p>El proceso se detuvo después de alcanzar el número máximo de errores de aplicación. Más detalles a continuación.</p> | E5: <p>Der Prozess wurde gestoppt, nachdem die in der Konfigurationsdatei definierte maximale Anzahl von Systemfehlern erreicht wurde. Anbei erhalten Sie das Status Report der Roboter Durchlauf.</p>
A6: StatusReport_SummaryMessage | B6: <p>Summary: <br>In total {0} Transaction(s) were processed. {1} Transaction(s) were successful and {2} Transaction(s) were not successful. <br><br>Abnormalities: {3}</p> | C6: <p>Résumé : <br>Au total, {0} Transaction(s) ont été traitées. {1} Transaction(s) ont réussi et {2} Transaction(s) n’ont pas réussi. <br><br>Anomalies : {3}</p> | D6: <p>Resumen: <br>En total se procesaron {0} Transacción(es). {1} Transacción(es) exitosa(s) y {2} Transacción(es) no exitosa(s). <br><br>Anomalías: {3}</p> | E6: <p>Zusammenfassung: <br>In total wurden {0} Transaktion(en) verarbeitet. {1} Transaktion(en) waren erfolgreich und {2} Transaktion(en) waren fehlerhaft.<br><br>Auffälligkeiten: {3}</p>
A7: StatusReport_SummaryMessage_NoData | B7: <p>Summary: <br>No transaction data was found. Please check the process for more details.</p> | C7: <p>Résumé : <br>Aucune donnée de transaction n’a été trouvée. Veuillez vérifier le processus pour plus de détails.</p> | D7: <p>Resumen: <br> No se han encontrado datos de transacción. Por favor, compruebe si hay errores en el proceso.</p> | E7: <p>Zusammenfassung: <br>Keine Transaktionsdaten gefunden, Bitte überprüfen Sie den Prozess auf mögliche Fehler.</p>
A8: ProcessStarted_Mail_Subject | B8: %Process% - Process Started | C8: %Process% - Process Started
A9: ProcessStarted_EmailBody | B9: <p>The performer process has successfully started and will now begin to process work items in the queue (if there are any).</p> | C9: <p>Le processus d’exécution a démarré avec succès et va maintenant commencer à traiter les éléments de travail dans la file d’attente (s’il y en a).</p>
A10: SE_Mail_Subject | B10: %ProcessName% - System Exception | C10: %ProcessName% - System Exception
A11: SE_Mail_CustomMessage_AtInit | B11: <p>The %Process% was abrupted due to a unexpected error in the initializing stage. Please inform your RPA contact person.</p> | C11: <p>Le %Process% a été interrompu en raison d’une erreur inattendue lors de l’étape d’initialisation. Veuillez informer votre personne de contact RPA.</p> | D11: <p>El %Process% se interrumpió debido a un error inesperado en la etapa de inicialización. Por favor, informe a su persona de contacto de RPA.</p> | E11: <p>Der %Process% wurde aufgrund eines unerwarteten Fehlers in der Initialisierung-Phase abgebrochen. Bitte informieren Sie Ihren RPA Ansprechpartner.</p>
A12: SE_Mail_CustomMessage | B12: <p>The transaction with ID %ID% was abrupted, because of an unexpected error. A Screenshot and a log-file are attached to this mail. The process will continue with the next transaction. You will receive a status report when all transactions are processed. <p>Message - Process Details:<br />%ErrorMessage%</p> <p>Message - Activity source:<br />%ErrorSource%</p> </p> | C12: <p>La transaction avec l’ID %ID% , avec le collaborateur %COLLABORATEUR% , a été interrompue, en raison d’une erreur inattendue. Une capture d’écran et un fichier journal sont joints à ce courrier. Le processus se poursuivra avec la prochaine transaction. Vous recevrez un rapport d’état lorsque toutes les transactions seront traitées. <p>Message - Détails du processus:<br />%ErrorMessage%</p> <p>Message - Source de l’activité:<br />%ErrorSource%</p> </p> | D12: <p>La transacción con ID %ID% se interrumpió debido a un error inesperado. Adjunto podrá ver una captura de pantalla y un archivo de registro. El proceso continuará con la próxima transacción. Recibirá un informe de estado cuando se procesen todas las transacciones. <p>Mensaje - Detalles técnicos del proceso:<br />%ErrorMessage%</p> <p>Mensaje - Fuente de actividad:<br />%ErrorSource%</p> </p> | E12: <p>Die transaktion mit ID %ID% wurde aufgrund eines unerwarteten Fehlers abgebrochen. Ein Screenshot und logdatei finden Sie im Anhang dieser Mail. Der Prozess l&amp;auml;uft weiter bis alle Transaktionen abgearbeitet worden sind. Am Ende des Prozesses wird Ihnen eine Protokolldatei zugeschickt. <p>Meldung - Prozesstechnische Details:<br />%ErrorMessage%</p> <p>Meldung - Activity source:<br />%ErrorSource%</p> </p>
A13: BRE_Mail_Subject | B13: %ProcessName% - Business Rule Exception | C13: %ProcessName% - Casier judiciaire non lisible par le robot pour le collaborateur %COLLABORATEUR% , Matricule : %MATRICULE% - Business Rule Exception
A14: BRE_Mail_CustomMessage | B14: <p>The transaction with ID %ID% was abrupted, because of a defined error. The process will continue with the next transaction. You will receive a status report when all transactions are processed. <p>Error cause:<br />%ErrorMessage%</p></p> | C14: <p>La transaction avec l’ID %ID% , avec le collaborateur %COLLABORATEUR% , a été interrompue, en raison d’une erreur définie. Le processus se poursuivra avec la prochaine transaction. Vous recevrez un rapport d’état lorsque toutes les transactions seront traitées. <p>Cause de l’erreur:<br />%ErrorMessage%</p></p> | D14: <p>La transacción con ID %ID% se interrumpió debido a un error de negocio. El proceso continuará con la próxima transacción. Recibirá un informe de estado cuando se procesen todas las transacciones. <p>La causa del error:<br />%ErrorMessage%</p></p> | E14: <p>Die transaktion mit ID %ID% ist auf einen definierten Fehler gesto&amp;szlig;en und wurde abgebrochen. Der Prozess l&amp;auml;uft weiter bis alle Transaktionen abgearbeitet worden sind. Am Ende des Prozesses wird Ihnen eine Protokolldatei zugeschickt. <p>Fehlerursache:<br />%ErrorMessage%</p></p>

Sheet DataValidation
A1: Language | B1: Boolean | C1: DispatcherLogic | D1: EmailType
A2: French | B2: TRUE | C2: Dispatcher integrated in Performer | D2: Outlook
A3: English | B3: FALSE | C3: Separate Dispatcher - Performer | D3: Office 365
A4: Spanish | D4: SMTP
A5: German
